Workbook
Name Slicer_Campaign_Name: #N/A
Name Slicer_Content_Type: #N/A
Name Slicer_Platform: #N/A

Sheet TASK 1
A1: Post ID | B1: Platform | C1: Date | D1: Content Type | E1: Post Text | F1: Likes | G1: Shares | H1: Comments | I1: Impressions | J1: Reach | K1: Clicks | L1: Hashtags Used | M1: Campaign_Name | N1: Campaign Start Date | O1: Campaign End Date | P1: Column1 | Q1: Engagement | R1: Engagement Rate | S1: Campaign Start Date2 | T1: Campaign End Date3 | U1: Campaign Category | V1: Campaign Budget | W1: ROI | X1: Follower Growth | Y1: Week Number | Z1: Ad Spend
A2: P001 | B2: Twitter | C2: 45649 | D2: Reel | E2: Check out our latest reel on twitter! | F2: 1461 | G2: 184 | H2: 344 | I2: 21915 | J2: 21675 | K2: 15 | L2: #FutureOfDriving | M2: CybertruckLaunch | N2: 45458 | O2: 45488 | P2: Before Campaign | Q2: =Table1_2[[#This Row],[Likes]]+Table1_2[[#This Row],[Shares]]+Table1_2[[#This Row],[Comments]] -> 1989 | R2: =(Table1_2[[#This Row],[Likes]]+Table1_2[[#This Row],[Shares]]+Table1_2[[#This Row],[Comments]])/Table1_2[[#This Row],[Impressions]] -> 0.090759754 | S2: =_xlfn.XLOOKUP(Table1_2[[#This Row],[Campaign_Name]],'Campaign Metadata'!A:A,'Campaign Metadata'!B:B,"not found",0) -> 45458 | T2: =_xlfn.XLOOKUP(Table1_2[[#This Row],[Campaign_Name]],'Campaign Metadata'!A:A,'Campaign Metadata'!C:C,"not found",0) -> 45488 | U2: =IF(AND(Table1_2[[#This Row],[Date]]>=Table1_2[[#This Row],[Campaign Start Date2]],Table1_2[[#This Row],[Date]]<=Table1_2[[#This Row],[Campaign End Date3]]),"During Campaign","Before Campaign") -> Before Campaign | V2: =_xlfn.XLOOKUP(Table1_2[[#This Row],[Campaign_Name]],'Campaign Metadata'!A:A,'Campaign Metadata'!E:E,"Not Available",0) -> 150000 | W2: =Table1_2[[#This Row],[Engagement]]/Table1_2[[#This Row],[Campaign Budget]] -> 0.01326 | X2: =_xlfn.XLOOKUP(Table1_2[[#This Row],[Platform]],'Engagement Summary'!B:B,'Engagement Summary'!H:H,"Not Available",0) -> 415 | Y2: =WEEKNUM(Table1_2[[#This Row],[Date]]) -> 52 | Z2: =_xlfn.XLOOKUP(Table1_2[[#This Row],[Platform]],'Engagement Summary'!B:B,'Engagement Summary'!G:G,"Notavailable",0) -> 26752
A3: P001 | B3: Twitter | C3: 45649 | D3: Reel | E3: Check out our latest reel on twitter! | F3: 1461 | G3: 184 | H3: 344 | I3: 21915 | J3: 21675 | K3: 15 | L3: #AnytimeIsTeslaTime | M3: CybertruckLaunch | N3: 45458 | O3: 45488 | P3: Before Campaign | Q3: =Table1_2[[#This Row],[Likes]]+Table1_2[[#This Row],[Shares]]+Table1_2[[#This Row],[Comments]] -> 1989 | R3: =(Table1_2[[#This Row],[Likes]]+Table1_2[[#This Row],[Shares]]+Table1_2[[#This Row],[Comments]])/Table1_2[[#This Row],[Impressions]] -> 0.090759754 | S3: =_xlfn.XLOOKUP(Table1_2[[#This Row],[Campaign_Name]],'Campaign Metadata'!A:A,'Campaign Metadata'!B:B,"not found",0) -> 45458 | T3: =_xlfn.XLOOKUP(Table1_2[[#This Row],[Campaign_Name]],'Campaign Metadata'!A:A,'Campaign Metadata'!C:C,"not found",0) -> 45488 | U3: =IF(AND(Table1_2[[#This Row],[Date]]>=Table1_2[[#This Row],[Campaign Start Date2]],Table1_2[[#This Row],[Date]]<=Table1_2[[#This Row],[Campaign End Date3]]),"During Campaign","Before Campaign") -> Before Campaign | V3: =_xlfn.XLOOKUP(Table1_2[[#This Row],[Campaign_Name]],'Campaign Metadata'!A:A,'Campaign Metadata'!E:E,"Not Available",0) -> 150000 | W3: =Table1_2[[#This Row],[Engagement]]/Table1_2[[#This Row],[Campaign Budget]] -> 0.01326 | X3: =_xlfn.XLOOKUP(Table1_2[[#This Row],[Platform]],'Engagement Summary'!B:B,'Engagement Summary'!H:H,"Not Available",0) -> 415 | Y3: =WEEKNUM(Table1_2[[#This Row],[Date]]) -> 52 | Z3: =_xlfn.XLOOKUP(Table1_2[[#This Row],[Platform]],'Engagement Summary'!B:B,'Engagement Summary'!G:G,"Notavailable",0) -> 26752
A4: P002 | B4: Twitter | C4: 45750 | D4: Text | E4: Check out our latest text on twitter! | F4: 4054 | G4: 389 | H4: 493 | I4: 64864 | J4: 64383 | K4: 117 | L4: #TeslaCoInnovation | M4: ModelYCampaign | N4: 45566 | O4: 45596 | P4: Before Campaign | Q4: =Table1_2[[#This Row],[Likes]]+Table1_2[[#This Row],[Shares]]+Table1_2[[#This Row],[Comments]] -> 4936 | R4: =(Table1_2[[#This Row],[Likes]]+Table1_2[[#This Row],[Shares]]+Table1_2[[#This Row],[Comments]])/Table1_2[[#This Row],[Impressions]] -> 0.076097681 | S4: =_xlfn.XLOOKUP(Table1_2[[#This Row],[Campaign_Name]],'Campaign Metadata'!A:A,'Campaign Metadata'!B:B,"not found",0) -> 45566 | T4: =_xlfn.XLOOKUP(Table1_2[[#This Row],[Campaign_Name]],'Campaign Metadata'!A:A,'Campaign Metadata'!C:C,"not found",0) -> 45596 | U4: =IF(AND(Table1_2[[#This Row],[Date]]>=Table1_2[[#This Row],[Campaign Start Date2]],Table1_2[[#This Row],[Date]]<=Table1_2[[#This Row],[Campaign End Date3]]),"During Campaign","Before Campaign") -> Before Campaign | V4: =_xlfn.XLOOKUP(Table1_2[[#This Row],[Campaign_Name]],'Campaign Metadata'!A:A,'Campaign Metadata'!E:E,"Not Available",0) -> 200000 | W4: =Table1_2[[#This Row],[Engagement]]/Table1_2[[#This Row],[Campaign Budget]] -> 0.02468 | X4: =_xlfn.XLOOKUP(Table1_2[[#This Row],[Platform]],'Engagement Summary'!B:B,'Engagement Summary'!H:H,"Not Available",0) -> 415 | Y4: =WEEKNUM(Table1_2[[#This Row],[Date]]) -> 14 | Z4: =_xlfn.XLOOKUP(Table1_2[[#This Row],[Platform]],'Engagement Summary'!B:B,'Engagement Summary'!G:G,"Notavailable",0) -> 26752
A5: P002 | B5: Twitter | C5: 45750 | D5: Text | E5: Check out our latest text on twitter! | F5: 4054 | G5: 389 | H5: 493 | I5: 64864 | J5: 64383 | K5: 117 | L5: #BetterWithTesla | M5: ModelYCampaign | N5: 45566 | O5: 45596 | P5: Before Campaign | Q5: =Table1_2[[#This Row],[Likes]]+Table1_2[[#This Row],[Shares]]+Table1_2[[#This Row],[Comments]] -> 4936 | R5: =(Table1_2[[#This Row],[Likes]]+Table1_2[[#This Row],[Shares]]+Table1_2[[#This Row],[Comments]])/Table1_2[[#This Row],[Impressions]] -> 0.076097681 | S5: =_xlfn.XLOOKUP(Table1_2[[#This Row],[Campaign_Name]],'Campaign Metadata'!A:A,'Campaign Metadata'!B:B,"not found",0) -> 45566 | T5: =_xlfn.XLOOKUP(Table1_2[[#This Row],[Campaign_Name]],'Campaign Metadata'!A:A,'Campaign Metadata'!C:C,"not found",0) -> 45596 | U5: =IF(AND(Table1_2[[#This Row],[Date]]>=Table1_2[[#This Row],[Campaign Start Date2]],Table1_2[[#This Row],[Date]]<=Table1_2[[#This Row],[Campaign End Date3]]),"During Campaign","Before Campaign") -> Before Campaign | V5: =_xlfn.XLOOKUP(Table1_2[[#This Row],[Campaign_Name]],'Campaign Metadata'!A:A,'Campaign Metadata'!E:E,"Not Available",0) -> 200000 | W5: =Table1_2[[#This Row],[Engagement]]/Table1_2[[#This Row],[Campaign Budget]] -> 0.02468 | X5: =_xlfn.XLOOKUP(Table1_2[[#This Row],[Platform]],'Engagement Summary'!B:B,'Engagement Summary'!H:H,"Not Available",0) -> 415 | Y5: =WEEKNUM(Table1_2[[#This Row],[Date]]) -> 14 | Z5: =_xlfn.XLOOKUP(Table1_2[[#This Row],[Platform]],'Engagement Summary'!B:B,'Engagement Summary'!G:G,"Notavailable",0) -> 26752
A6: P003 | B6: YouTube | C6: 45789 | D6: Reel | E6: Check out our latest reel on youtube! | F6: 2795 | G6: 105 | H6: 49 | I6: 53105 | J6: 52307 | K6: 204 | L6: #TeslaCoInnovation | M6: FSDUpdate | N6: 45651 | O6: 45667 | P6: Before Campaign | Q6: =Table1_2[[#This Row],[Likes]]+Table1_2[[#This Row],[Shares]]+Table1_2[[#This Row],[Comments]] -> 2949 | R6: =(Table1_2[[#This Row],[Likes]]+Table1_2[[#This Row],[Shares]]+Table1_2[[#This Row],[Comments]])/Table1_2[[#This Row],[Impressions]] -> 0.055531494 | S6: =_xlfn.XLOOKUP(Table1_2[[#This Row],[Campaign_Name]],'Campaign Metadata'!A:A,'Campaign Metadata'!B:B,"not found",0) -> 45651 | T6: =_xlfn.XLOOKUP(Table1_2[[#This Row],[Campaign_Name]],'Campaign Metadata'!A:A,'Campaign Metadata'!C:C,"not found",0) -> 45667 | U6: =IF(AND(Table1_2[[#This Row],[Date]]>=Table1_2[[#This Row],[Campaign Start Date2]],Table1_2[[#This Row],[Date]]<=Table1_2[[#This Row],[Campaign End Date3]]),"During Campaign","Before Campaign") -> Before Campaign | V6: =_xlfn.XLOOKUP(Table1_2[[#This Row],[Campaign_Name]],'Campaign Metadata'!A:A,'Campaign Metadata'!E:E,"Not Available",0) -> 250000 | W6: =Table1_2[[#This Row],[Engagement]]/Table1_2[[#This Row],[Campaign Budget]] -> 0.011796 | X6: =_xlfn.XLOOKUP(Table1_2[[#This Row],[Platform]],'Engagement Summary'!B:B,'Engagement Summary'!H:H,"Not Available",0) -> 1090 | Y6: =WEEKNUM(Table1_2[[#This Row],[Date]]) -> 20 | Z6: =_xlfn.XLOOKUP(Table1_2[[#This Row],[Platform]],'Engagement Summary'!B:B,'Engagement Summary'!G:G,"Notavailable",0) -> 30671
A7: P004 | B7: Instagram | C7: 45516 | D7: Story | E7: Check out our latest story on instagram! | F7: 2404 | G7: 363 | H7: 138 | I7: 19232 | J7: 18636 | K7: 128 | L7: #EVRevolution | M7: SustainabilityDrive | N7: 45717 | O7: 45747 | P7: Before Campaign | Q7: =Table1_2[[#This Row],[Likes]]+Table1_2[[#This Row],[Shares]]+Table1_2[[#This Row],[Comments]] -> 2905 | R7: =(Table1_2[[#This Row],[Likes]]+Table1_2[[#This Row],[Shares]]+Table1_2[[#This Row],[Comments]])/Table1_2[[#This Row],[Impressions]] -> 0.15105033 | S7: =_xlfn.XLOOKUP(Table1_2[[#This Row],[Campaign_Name]],'Campaign Metadata'!A:A,'Campaign Metadata'!B:B,"not found",0) -> 45717 | T7: =_xlfn.XLOOKUP(Table1_2[[#This Row],[Campaign_Name]],'Campaign Metadata'!A:A,'Campaign Metadata'!C:C,"not found",0) -> 45747 | U7: =IF(AND(Table1_2[[#This Row],[Date]]>=Table1_2[[#This Row],[Campaign Start Date2]],Table1_2[[#This Row],[Date]]<=Table1_2[[#This Row],[Campaign End Date3]]),"During Campaign","Before Campaign") -> Before Campaign | V7: =_xlfn.XLOOKUP(Table1_2[[#This Row],[Campaign_Name]],'Campaign Metadata'!A:A,'Campaign Metadata'!E:E,"Not Available",0) -> 180000 | W7: =Table1_2[[#This Row],[Engagement]]/Table1_2[[#This Row],[Campaign Budget]] -> 0.016138889 | X7: =_xlfn.XLOOKUP(Table1_2[[#This Row],[Platform]],'Engagement Summary'!B:B,'Engagement Summary'!H:H,"Not Available",0) -> 1047 | Y7: =WEEKNUM(Table1_2[[#This Row],[Date]]) -> 33 | Z7: =_xlfn.XLOOKUP(Table1_2[[#This Row],[Platform]],'Engagement Summary'!B:B,'Engagement Summary'!G:G,"Notavailable",0) -> 5904
A8: P005 | B8: YouTube | C8: 45469 | D8: Reel | E8: Check out our latest reel on youtube! | F8: 3557 | G8: 687 | H8: 424 | I8: 71140 | J8: 70701 | K8: 224 | L8: #EVRevolution | M8: CybertruckLaunch | N8: 45458 | O8: 45488 | P8: Before Campaign | Q8: =Table1_2[[#This Row],[Likes]]+Table1_2[[#This Row],[Shares]]+Table1_2[[#This Row],[Comments]] -> 4668 | R8: =(Table1_2[[#This Row],[Likes]]+Table1_2[[#This Row],[Shares]]+Table1_2[[#This Row],[Comments]])/Table1_2[[#This Row],[Impressions]] -> 0.065617093 | S8: =_xlfn.XLOOKUP(Table1_2[[#This Row],[Campaign_Name]],'Campaign Metadata'!A:A,'Campaign Metadata'!B:B,"not found",0) -> 45458 | T8: =_xlfn.XLOOKUP(Table1_2[[#This Row],[Campaign_Name]],'Campaign Metadata'!A:A,'Campaign Metadata'!C:C,"not found",0) -> 45488 | U8: =IF(AND(Table1_2[[#This Row],[Date]]>=Table1_2[[#This Row],[Campaign Start Date2]],Table1_2[[#This Row],[Date]]<=Table1_2[[#This Row],[Campaign End Date3]]),"During Campaign","Before Campaign") -> During Campaign | V8: =_xlfn.XLOOKUP(Table1_2[[#This Row],[Campaign_Name]],'Campaign Metadata'!A:A,'Campaign Metadata'!E:E,"Not Available",0) -> 150000 | W8: =Table1_2[[#This Row],[Engagement]]/Table1_2[[#This Row],[Campaign Budget]] -> 0.03112 | X8: =_xlfn.XLOOKUP(Table1_2[[#This Row],[Platform]],'Engagement Summary'!B:B,'Engagement Summary'!H:H,"Not Available",0) -> 1090 | Y8: =WEEKNUM(Table1_2[[#This Row],[Date]]) -> 26 | Z8: =_xlfn.XLOOKUP(Table1_2[[#This Row],[Platform]],'Engagement Summary'!B:B,'Engagement Summary'!G:G,"Notavailable",0) -> 30671
A9: P005 | B9: YouTube | C9: 45469 | D9: Reel | E9: Check out our latest reel on youtube! | F9: 3557 | G9: 687 | H9: 424 | I9: 71140 | J9: 70701 | K9: 224 | L9: #TeslaCoInnovation | M9: CybertruckLaunch | N9: 45458 | O9: 45488 | P9: Before Campaign | Q9: =Table1_2[[#This Row],[Likes]]+Table1_2[[#This Row],[Shares]]+Table1_2[[#This Row],[Comments]] -> 4668 | R9: =(Table1_2[[#This Row],[Likes]]+Table1_2[[#This Row],[Shares]]+Table1_2[[#This Row],[Comments]])/Table1_2[[#This Row],[Impressions]] -> 0.065617093 | S9: =_xlfn.XLOOKUP(Table1_2[[#This Row],[Campaign_Name]],'Campaign Metadata'!A:A,'Campaign Metadata'!B:B,"not found",0) -> 45458 | T9: =_xlfn.XLOOKUP(Table1_2[[#This Row],[Campaign_Name]],'Campaign Metadata'!A:A,'Campaign Metadata'!C:C,"not found",0) -> 45488 | U9: =IF(AND(Table1_2[[#This Row],[Date]]>=Table1_2[[#This Row],[Campaign Start Date2]],Table1_2[[#This Row],[Date]]<=Table1_2[[#This Row],[Campaign End Date3]]),"During Campaign","Before Campaign") -> During Campaign | V9: =_xlfn.XLOOKUP(Table1_2[[#This Row],[Campaign_Name]],'Campaign Metadata'!A:A,'Campaign Metadata'!E:E,"Not Available",0) -> 150000 | W9: =Table1_2[[#This Row],[Engagement]]/Table1_2[[#This Row],[Campaign Budget]] -> 0.03112 | X9: =_xlfn.XLOOKUP(Table1_2[[#This Row],[Platform]],'Engagement Summary'!B:B,'Engagement Summary'!H:H,"Not Available",0) -> 1090 | Y9: =WEEKNUM(Table1_2[[#This Row],[Date]]) -> 26 | Z9: =_xlfn.XLOOKUP(Table1_2[[#This Row],[Platform]],'Engagement Summary'!B:B,'Engagement Summary'!G:G,"Notavailable",0) -> 30671
A10: P006 | B10: Facebook | C10: 45596 | D10: Carousel | E10: Check out our latest carousel on facebook! | F10: 2945 | G10: 930 | H10: 355 | I10: 23560 | J10: 23275 | K10: 256 | L10: #TeslaCoInnovation | M10: ModelYCampaign | N10: 45566 | O10: 45596 | P10: Before Campaign | Q10: =Table1_2[[#This Row],[Likes]]+Table1_2[[#This Row],[Shares]]+Table1_2[[#This Row],[Comments]] -> 4230 | R10: =(Table1_2[[#This Row],[Likes]]+Table1_2[[#This Row],[Shares]]+Table1_2[[#This Row],[Comments]])/Table1_2[[#This Row],[Impressions]] -> 0.1795416 | S10: =_xlfn.XLOOKUP(Table1_2[[#This Row],[Campaign_Name]],'Campaign Metadata'!A:A,'Campaign Metadata'!B:B,"not found",0) -> 45566 | T10: =_xlfn.XLOOKUP(Table1_2[[#This Row],[Campaign_Name]],'Campaign Metadata'!A:A,'Campaign Metadata'!C:C,"not found",0) -> 45596 | U10: =IF(AND(Table1_2[[#This Row],[Date]]>=Table1_2[[#This Row],[Campaign Start Date2]],Table1_2[[#This Row],[Date]]<=Table1_2[[#This Row],[Campaign End Date3]]),"During Campaign","Before Campaign") -> During Campaign | V10: =_xlfn.XLOOKUP(Table1_2[[#This Row],[Campaign_Name]],'Campaign Metadata'!A:A,'Campaign Metadata'!E:E,"Not Available",0) -> 200000 | W10: =Table1_2[[#This Row],[Engagement]]/Table1_2[[#This Row],[Campaign Budget]] -> 0.02115 | X10: =_xlfn.XLOOKUP(Table1_2[[#This Row],[Platform]],'Engagement Summary'!B:B,'Engagement Summary'!H:H,"Not Available",0) -> 1002 | Y10: =WEEKNUM(Table1_2[[#This Row],[Date]]) -> 44 | Z10: =_xlfn.XLOOKUP(Table1_2[[#This Row],[Platform]],'Engagement Summary'!B:B,'Engagement Summary'!G:G,"Notavailable",0) -> 9566
A11: P007 | B11: Twitter | C11: 45467 | D11: Carousel | E11: Check out our latest carousel on twitter! | F11: 3860 | G11: 201 | H11: 279 | I11: 61760 | J11: 61660 | K11: 235 | L11: #TeslaCoInnovation | M11: ModelYCampaign | N11: 45566 | O11: 45596 | P11: Before Campaign | Q11: =Table1_2[[#This Row],[Likes]]+Table1_2[[#This Row],[Shares]]+Table1_2[[#This Row],[Comments]] -> 4340 | R11: =(Table1_2[[#This Row],[Likes]]+Table1_2[[#This Row],[Shares]]+Table1_2[[#This Row],[Comments]])/Table1_2[[#This Row],[Impressions]] -> 0.070272021 | S11: =_xlfn.XLOOKUP(Table1_2[[#This Row],[Campaign_Name]],'Campaign Metadata'!A:A,'Campaign Metadata'!B:B,"not found",0) -> 45566 | T11: =_xlfn.XLOOKUP(Table1_2[[#This Row],[Campaign_Name]],'Campaign Metadata'!A:A,'Campaign Metadata'!C:C,"not found",0) -> 45596 | U11: =IF(AND(Table1_2[[#This Row],[Date]]>=Table1_2[[#This Row],[Campaign Start Date2]],Table1_2[[#This Row],[Date]]<=Table1_2[[#This Row],[Campaign End Date3]]),"During Campaign","Before Campaign") -> Before Campaign | V11: =_xlfn.XLOOKUP(Table1_2[[#This Row],[Campaign_Name]],'Campaign Metadata'!A:A,'Campaign Metadata'!E:E,"Not Available",0) -> 200000 | W11: =Table1_2[[#This Row],[Engagement]]/Table1_2[[#This Row],[Campaign Budget]] -> 0.0217 | X11: =_xlfn.XLOOKUP(Table1_2[[#This Row],[Platform]],'Engagement Summary'!B:B,'Engagement Summary'!H:H,"Not Available",0) -> 415 | Y11: =WEEKNUM(Table1_2[[#This Row],[Date]]) -> 26 | Z11: =_xlfn.XLOOKUP(Table1_2[[#This Row],[Platform]],'Engagement Summary'!B:B,'Engagement Summary'!G:G,"Notavailable",0) -> 26752
A12: P008 | B12: YouTube | C12: 45486 | D12: Image | E12: Check out our latest image on youtube! | F12: 3929 | G12: 262 | H12: 278 | I12: 43219 | J12: 42841 | K12: 39 | L12: #EVRevolution | M12: SustainabilityDrive | N12: 45717 | O12: 45747 | P12: Before Campaign | Q12: =Table1_2[[#This Row],[Likes]]+Table1_2[[#This Row],[Shares]]+Table1_2[[#This Row],[Comments]] -> 4469 | R12: =(Table1_2[[#This Row],[Likes]]+Table1_2[[#This Row],[Shares]]+Table1_2[[#This Row],[Comments]])/Table1_2[[#This Row],[Impressions]] -> 0.1034036 | S12: =_xlfn.XLOOKUP(Table1_2[[#This Row],[Campaign_Name]],'Campaign Metadata'!A:A,'Campaign Metadata'!B:B,"not found",0) -> 45717 | T12: =_xlfn.XLOOKUP(Table1_2[[#This Row],[Campaign_Name]],'Campaign Metadata'!A:A,'Campaign Metadata'!C:C,"not found",0) -> 45747 | U12: =IF(AND(Table1_2[[#This Row],[Date]]>=Table1_2[[#This Row],[Campaign Start Date2]],Table1_2[[#This Row],[Date]]<=Table1_2[[#This Row],[Campaign End Date3]]),"During Campaign","Before Campaign") -> Before Campaign | V12: =_xlfn.XLOOKUP(Table1_2[[#This Row],[Campaign_Name]],'Campaign Metadata'!A:A,'Campaign Metadata'!E:E,"Not Available",0) -> 180000 | W12: =Table1_2[[#This Row],[Engagement]]/Table1_2[[#This Row],[Campaign Budget]] -> 0.024827778 | X12: =_xlfn.XLOOKUP(Table1_2[[#This Row],[Platform]],'Engagement Summary'!B:B,'Engagement Summary'!H:H,"Not Available",0) -> 1090 | Y12: =WEEKNUM(Table1_2[[#This Row],[Date]]) -> 28 | Z12: =_xlfn.XLOOKUP(Table1_2[[#This Row],[Platform]],'Engagement Summary'!B:B,'Engagement Summary'!G:G,"Notavailable",0) -> 30671
A13: P009 | B13: Facebook | C13: 45534 | D13: Text | E13: Check out our latest text on facebook! | F13: 3784 | G13: 808 | H13: 404 | I13: 56760 | J13: 56343 | K13: 131 | L13: #TeslaCoInnovation | M13: ModelYCampaign | N13: 45566 | O13: 45596 | P13: Before Campaign | Q13: =Table1_2[[#This Row],[Likes]]+Table1_2[[#This Row],[Shares]]+Table1_2[[#This Row],[Comments]] -> 4996 | R13: =(Table1_2[[#This Row],[Likes]]+Table1_2[[#This Row],[Shares]]+Table1_2[[#This Row],[Comments]])/Table1_2[[#This Row],[Impressions]] -> 0.088019732 | S13: =_xlfn.XLOOKUP(Table1_2[[#This Row],[Campaign_Name]],'Campaign Metadata'!A:A,'Campaign Metadata'!B:B,"not found",0) -> 45566 | T13: =_xlfn.XLOOKUP(Table1_2[[#This Row],[Campaign_Name]],'Campaign Metadata'!A:A,'Campaign Metadata'!C:C,"not found",0) -> 45596 | U13: =IF(AND(Table1_2[[#This Row],[Date]]>=Table1_2[[#This Row],[Campaign Start Date2]],Table1_2[[#This Row],[Date]]<=Table1_2[[#This Row],[Campaign End Date3]]),"During Campaign","Before Campaign") -> Before Campaign | V13: =_xlfn.XLOOKUP(Table1_2[[#This Row],[Campaign_Name]],'Campaign Metadata'!A:A,'Campaign Metadata'!E:E,"Not Available",0) -> 200000 | W13: =Table1_2[[#This Row],[Engagement]]/Table1_2[[#This Row],[Campaign Budget]] -> 0.02498 | X13: =_xlfn.XLOOKUP(Table1_2[[#This Row],[Platform]],'Engagement Summary'!B:B,'Engagement Summary'!H:H,"Not Available",0) -> 1002 | Y13: =WEEKNUM(Table1_2[[#This Row],[Date]]) -> 35 | Z13: =_xlfn.XLOOKUP(Table1_2[[#This Row],[Platform]],'Engagement Summary'!B:B,'Engagement Summary'!G:G,"Notavailable",0) -> 9566
... A340: P300 | B340: Twitter | C340: 45535 | D340: Carousel | E340: Check out our latest carousel on twitter! | F340: 4494 | G340: 717 | H340: 45 | I340: 62916 | J340: 62688 | K340: 191 | L340: #BetterWithTesla | M340: CybertruckLaunch | N340: 45458 | O340: 45488 | P340: Before Campaign | Q340: =Table1_2[[#This Row],[Likes]]+Table1_2[[#This Row],[Shares]]+Table1_2[[#This Row],[Comments]] -> 5256 | R340: =(Table1_2[[#This Row],[Likes]]+Table1_2[[#This Row],[Shares]]+Table1_2[[#This Row],[Comments]])/Table1_2[[#This Row],[Impressions]] -> 0.083539958 | S340: =_xlfn.XLOOKUP(Table1_2[[#This Row],[Campaign_Name]],'Campaign Metadata'!A:A,'Campaign Metadata'!B:B,"not found",0) -> 45458 | T340: =_xlfn.XLOOKUP(Table1_2[[#This Row],[Campaign_Name]],'Campaign Metadata'!A:A,'Campaign Metadata'!C:C,"not found",0) -> 45488 | U340: =IF(AND(Table1_2[[#This Row],[Date]]>=Table1_2[[#This Row],[Campaign Start Date2]],Table1_2[[#This Row],[Date]]<=Table1_2[[#This Row],[Campaign End Date3]]),"During Campaign","Before Campaign") -> Before Campaign | V340: =_xlfn.XLOOKUP(Table1_2[[#This Row],[Campaign_Name]],'Campaign Metadata'!A:A,'Campaign Metadata'!E:E,"Not Available",0) -> 150000 | W340: =Table1_2[[#This Row],[Engagement]]/Table1_2[[#This Row],[Campaign Budget]] -> 0.03504 | X340: =_xlfn.XLOOKUP(Table1_2[[#This Row],[Platform]],'Engagement Summary'!B:B,'Engagement Summary'!H:H,"Not Available",0) -> 415 | Y340: =WEEKNUM(Table1_2[[#This Row],[Date]]) -> 35 | Z340: =_xlfn.XLOOKUP(Table1_2[[#This Row],[Platform]],'Engagement Summary'!B:B,'Engagement Summary'!G:G,"Notavailable",0) -> 26752

Sheet TASK 2
D1: TASK 2
A2: Average Engagement Rate Per Platform
A3: Platform | B3: Average of Engagement Rate
A4: Facebook | B4: 0.12094203
A9: Key Findings: Instagram has the highest average
A10: engagement rate.
A12: Top 10 Tesla Posts with Highest Engagement
A13: Tesla Post | B13: Sum of Engagement
A14: P247 | B14: 12702
A15: P257 | B15: 11853
A16: P215 | B16: 5973
A17: P217 | B17: 5767
A18: P140 | B18: 5708
A19: P222 | B19: 5660
A20: P152 | B20: 5624
A21: P118 | B21: 5472
A22: P067 | B22: 5407
A23: P241 | B23: 5367
A24: Key Findings: Post number 280, a Youtube Video has the highest engagement over all the posts.
A26: Total Likes, Shares and Comments by Content Type and Platform
A27: Platform | B27: Total Likes | C27: Total Shares | D27: Total Comments
A28: Facebook
A29: Carousel | B29: 44476 | C29: 7400 | D29: 4589
A30: Image | B30: 80073 | C30: 14376 | D30: 7308
A31: Reel | B31: 46102 | C31: 7149 | D31: 3732
A32: Story | B32: 29405 | C32: 4950 | D32: 3223
A33: Text | B33: 35357 | C33: 5127 | D33: 4424
A34: Video | B34: 30553 | C34: 3718 | D34: 2579
A56: Key Findings: Introspecting into the above dataset, Facebook has the best engagement in image category, Instagram has the best engagement as stories, Twitter dominates in the carousel category
A57: and Videos are mostly viewed in Youtube.
A61: Top-Performing Hashtags
A62: Post Hashtags | B62: Average of Clicks
A63: #AnytimeIsTeslaTime | B63: 219
A64: #FutureOfDriving | B64: 158.41379
A65: #EVRevolution | B65: 145.03571
A66: #TeslaCoInnovation | B66: 136.41379
A67: #BetterWithTesla | B67: 116.5
A68: #SmoothLikeNitroTesla | B68: 24.5
A76: Key Findings:The above highlighted hashtags are the top-performing hashtags by average clicks. | E76: Key Findings:The above highlighted hashtags are the top-performing hashtags by average clicks. | I76: Key Findings:The above highlighted hashtags are the top-performing hashtags by average clicks. | M76: Key Findings:The above highlighted hashtags are the top-performing hashtags by average clicks.
A79: Average of Engagement by Platform
...

Sheet TASK 3
E1: TASK-3
A3: Platform with Highest Engagement
A4: Platform | B4: Sum of Engagement
A5: Facebook | B5: 334541
A10: The above highlighted cell: Facebook has the
A11: highest engagement.
A15: Follower Growth rates per Platform
A16: Platform | B16: Follower Growth Rate
A17: Facebook | B17: 0.27324953
A18: Instagram | B18: 0.28812661
A19: Twitter | B19: 0.46400128
A20: YouTube | B20: 0.45105333
A22: Twitter clearly has the highest follower growth rate.
A25: Engagement Vs Ad Spend per Platform
A26: Platform | B26: Average of Engagement_Rate | C26: Ad Spend
A27: Facebook | B27: 5.6486 | C27: 1379539
A28: Instagram | B28: 5.7156 | C28: 1164373
A29: Twitter | B29: 5.6558 | C29: 1060357
A30: YouTube | B30: 5.5588 | C30: 1228647
A32: Instagram clearly has the best engagement rate.
A42: Recommendation: As per the insights and findings, I suggest Tesla should follow a multi-platform strategy for advertisment. Introspecting into the insights, we should focus on all the platforms
A43: as per the content type. Since, Facebook has the highest engagement over images, we should have image advertised over Facebook. Likewise, instagram wins over stories, twitter over carousels,
A44: and youtube over videos. Overall, Tesla should put in money for advertisement over Instagram and Youtube, as both has the best overall turnover(Return of Investment) and engagement rate
A45: respectively.

Sheet TASK 4
E1: TASK-4
A13: Frequently Used Tesla Hashtags
A17: Hashtags Used | B17: Count of Posts
A18: #FutureOfDriving | B18: 29
A19: #TeslaCoInnovation | B19: 29
A20: #EVRevolution | B20: 28
A21: #AnytimeIsTeslaTime | B21: 3
A22: #BetterWithTesla | B22: 2
A23: #SmoothLikeNitroTesla | B23: 2
A25: Key Finding: #TeslaCoInnovation has the highest posts.
A30: Avg Performance by Hashtags Used
A34: Hashtags Used | B34: Average of Engagement Rate
A35: #SmoothLikeNitroTesla | B35: 0.13357645
A36: #TeslaCoInnovation | B36: 0.12889893
A37: #EVRevolution | B37: 0.12145134
A38: #FutureOfDriving | B38: 0.11424805
A39: #AnytimeIsTeslaTime | B39: 0.10994737
A40: #BetterWithTesla | B40: 0.099357075
A42: Key Finding: #EvRevolution and #TeslaCoInnovation
A43: has the highest average rate.
A45: Engagement By Content Type
A46: Content Type | B46: Average of Engagement Rate
A47: Story | B47: 0.15898978
A48: Video | B48: 0.12378368
A49: Carousel | B49: 0.1182059
A50: Image | B50: 0.11745425
A51: Text | B51: 0.11119518
A52: Reel | B52: 0.1098686
A54: Key Finding: Stories had the highest engagement by
A55: content type.
A63: Recommendations: As per the insights and findings, I would recommend Instagram for posting short stories, for carousels, Twitter would be the best. For advertising high-quality images, we should use Facebook. To demonstrate features and performance,
A64: review videos would be best to be advertised through Youtube.This recommendation is also supported by the fact that Twitter has the highest follower growth rate and Facebook has the highest engagement overall.
A65: Using tags like #AnytimeisTeslaTime and focussing on the reliability and overall features of Tesla cars and also aligning its advertisement over promoting Electric Vehicle culture and promoting environmental concerns to elevate sales.

Sheet TASK 5
D1: TASK-5
A2: Total & Average Impressions,Likes, Clicks per Campaign
A3: Campaign Name | B3: Sum of Likes | C3: Average of Likes | D3: Sum of Clicks | E3: Average of Clicks | F3: Sum of Impressions | G3: Average of Impressions
A4: notavailable | B4: 54737 | C4: 2880.8947 | D4: 3200 | E4: 168.42105 | F4: 661164 | G4: 34798.105
A5: CybertruckLaunch | B5: 33436 | C5: 2786.3333 | D5: 1812 | E5: 151 | F5: 470831 | G5: 39235.917
A6: SustainabilityDrive | B6: 51192 | C6: 2844 | D6: 2626 | E6: 145.88889 | F6: 678203 | G6: 37677.944
A7: ModelYCampaign | B7: 55180 | C7: 2627.619 | D7: 2893 | E7: 137.7619 | F7: 757676 | G7: 36079.81
A8: FSDUpdate | B8: 71421 | C8: 3105.2609 | D8: 3019 | E8: 131.26087 | F8: 954744 | G8: 41510.609
A26: Insights: Sustainability Drive Campaign had the highest likes, clicks and impressions.
A28: Engagement Uplift(During Vs Before Campaign)
A29: Campaign Name | B29: Average of Engagement | C29: Engagement Uplift
A30: CybertruckLaunch
A31: Before Campaign | B31: 3511.3636 | C31: =GETPIVOTDATA("Engagement",$A$29,"Campaign_Name","CybertruckLaunch","Campaign Category","During Campaign")-GETPIVOTDATA("Engagement",$A$29,"Campaign_Name","CybertruckLaunch","Campaign Category","Before Campaign") -> 596.63636
A32: During Campaign | B32: 4108
A33: FSDUpdate
A34: Before Campaign | B34: 3874.5217 | C34: =GETPIVOTDATA("Engagement",$A$29,"Campaign_Name","FSDUpdate","Campaign Category","During Campaign")-GETPIVOTDATA("Engagement",$A$29,"Campaign_Name","FSDUpdate","Campaign Category","Before Campaign") -> #REF!
A35: ModelYCampaign
A36: Before Campaign | B36: 3444.6111
A37: During Campaign | B37: 3506.3333 | C37: =GETPIVOTDATA("Engagement",$A$29,"Campaign_Name","ModelYCampaign","Campaign Category","During Campaign")-GETPIVOTDATA("Engagement",$A$29,"Campaign_Name","ModelYCampaign","Campaign Category","Before Campaign") -> 61.722222
A38: notavailable | B38: 3503.8947
A39: SustainabilityDrive
A40: Before Campaign | B40: 3675
A41: During Campaign | B41: 2399
C42: =GETPIVOTDATA("Engagement",$A$29,"Campaign_Name","SustainabilityDrive","Campaign Category","During Campaign")-GETPIVOTDATA("Engagement",$A$29,"Campaign_Name","SustainabilityDrive","Campaign Category","Before Campaign") -> -1276
A44: ModelYCampaign had the highest Engagement Uplift.
A46: Engagement Vs Spend(R.O.I)
A48: Campaign Name | B48: Average of ROI
A49: CybertruckLaunch | B49: 0.023740556
A50: FSDUpdate | B50: 0.015498087
A51: ModelYCampaign | B51: 0.017267143
A52: notavailable | B52: #VALUE!
A53: SustainabilityDrive | B53: 0.019629012
A56: Cybertruck launch has the highest average R.O.I.
A60: Strongest Follower Growth by Campaign
A62: Campaign Name | B62: Sum of Follower Growth
A63: CybertruckLaunch | B63: 12024
A64: FSDUpdate | B64: 23046
A65: ModelYCampaign | B65: 21042
A66: notavailable | B66: 19038
A67: SustainabilityDrive | B67: 18036
...

Sheet TASK 6
H1: TASK-6
A2: Weekly Follower Growth
A3: Platform | B3: Average of Follower Growth
A4: 1 | B4: 1002
A5: 2 | B5: 1002
A6: 3 | B6: 1002
A7: 4 | B7: 1002
A8: 5 | B8: 1002
A9: 6 | B9: 1002
A10: 7 | B10: 1002
A11: 8 | B11: 1002
A12: 9 | B12: 1002
A13: 10 | B13: 1002
A14: 11 | B14: 1002
A15: 13 | B15: 1002
... A28: 30 | B28: 1002
A29: 31 | B29: 1002 | D29: Insights: Week 16 had the lowest average follower growth and Week 51 the highest.
A30: 32 | B30: 1002
A31: 33 | B31: 1002
A32: 34 | B32: 1002
A33: 35 | B33: 1002
A34: 41 | B34: 1002
A35: 42 | B35: 1002
A36: 43 | B36: 1002
A37: 44 | B37: 1002
A38: 45 | B38: 1002
A39: 46 | B39: 1002
A40: 47 | B40: 1002
A41: 48 | B41: 1002
... A45: 52 | B45: 1002
C62: Peak Week of follower Gain
C64: Week Number | D64: Average of Net Follower
C65: 2 | D65: 889.25
C66: 3 | D66: 694.25
C67: 4 | D67: 903.5
C68: 5 | D68: 845.75
C69: 6 | D69: 548.5
C70: 7 | D70: 1320.25
C71: 8 | D71: 923.25
C72: 9 | D72: 1201.5
...

Sheet Sheet1
F1: TASK-7
B3: Project Explanation Video Link:
A4: https://www.loom.com/share/08be943f391c4daca3d44ada15bbf3f0

Sheet Dashboard
A1: TESLA SOCIAL MEDIA ANALYTICS REPORT
A2: OverView:
A3: This dashboard summarizes social post performance, campaign context, and paid support to reveal what drives engagement, reach, and growth across platforms and content types.

Sheet Posts
A1: Post ID | B1: Platform | C1: Date | D1: Content Type | E1: Post Text | F1: Likes | G1: Shares | H1: Comments | I1: Impressions | J1: Reach | K1: Clicks | L1: Hashtags Used | M1: Campaign_Name | N1: Campaign Start Date | O1: Campaign End Date | P1: Campaign Period
A2: P001 | B2: Twitter | C2: 2024-12-23 | D2: Reel | E2: Check out our latest reel on twitter! | F2: 1461 | G2: 184 | H2: 344 | I2: 21915 | J2: 21675 | K2: 15 | L2: #FutureOfDriving,#AnytimeIsTeslaTime | M2: CybertruckLaunch | N2: =_xlfn.XLOOKUP(Table1[[#This Row],[Campaign_Name]],'Campaign Metadata'!A:A,'Campaign Metadata'!B:B,"Notfound",0) -> 45458 | O2: =_xlfn.XLOOKUP(Table1[[#This Row],[Campaign_Name]],'Campaign Metadata'!A:A,'Campaign Metadata'!C:C,"Not found",0) -> 45488 | P2: =IF(AND(Table1[[#This Row],[Date]]>=Table1[[#This Row],[Campaign Start Date]],Table1[[#This Row],[Date]]<=Table1[[#This Row],[Campaign End Date]]),"During Campaign","Before Campaign") -> Before Campaign
A3: P002 | B3: Twitter | C3: 2025-04-03 | D3: Text | E3: Check out our latest text on twitter! | F3: 4054 | G3: 389 | H3: 493 | I3: 64864 | J3: 64383 | K3: 117 | L3: #TeslaCoInnovation,#BetterWithTesla | M3: ModelYCampaign | N3: =_xlfn.XLOOKUP(Table1[[#This Row],[Campaign_Name]],'Campaign Metadata'!A:A,'Campaign Metadata'!B:B,"Notfound",0) -> 45566 | O3: =_xlfn.XLOOKUP(Table1[[#This Row],[Campaign_Name]],'Campaign Metadata'!A:A,'Campaign Metadata'!C:C,"Not found",0) -> 45596 | P3: =IF(AND(Table1[[#This Row],[Date]]>=Table1[[#This Row],[Campaign Start Date]],Table1[[#This Row],[Date]]<=Table1[[#This Row],[Campaign End Date]]),"During Campaign","Before Campaign") -> Before Campaign
A4: P003 | B4: YouTube | C4: 2025-05-12 | D4: Reel | E4: Check out our latest reel on youtube! | F4: 2795 | G4: 105 | H4: 49 | I4: 53105 | J4: 52307 | K4: 204 | L4: #TeslaCoInnovation | M4: FSDUpdate | N4: =_xlfn.XLOOKUP(Table1[[#This Row],[Campaign_Name]],'Campaign Metadata'!A:A,'Campaign Metadata'!B:B,"Notfound",0) -> 45651 | O4: =_xlfn.XLOOKUP(Table1[[#This Row],[Campaign_Name]],'Campaign Metadata'!A:A,'Campaign Metadata'!C:C,"Not found",0) -> 45667 | P4: =IF(AND(Table1[[#This Row],[Date]]>=Table1[[#This Row],[Campaign Start Date]],Table1[[#This Row],[Date]]<=Table1[[#This Row],[Campaign End Date]]),"During Campaign","Before Campaign") -> Before Campaign
A5: P004 | B5: Instagram | C5: 2024-08-12 | D5: Story | E5: Check out our latest story on instagram! | F5: 2404 | G5: 363 | H5: 138 | I5: 19232 | J5: 18636 | K5: 128 | L5: #EVRevolution | M5: SustainabilityDrive | N5: =_xlfn.XLOOKUP(Table1[[#This Row],[Campaign_Name]],'Campaign Metadata'!A:A,'Campaign Metadata'!B:B,"Notfound",0) -> 45717 | O5: =_xlfn.XLOOKUP(Table1[[#This Row],[Campaign_Name]],'Campaign Metadata'!A:A,'Campaign Metadata'!C:C,"Not found",0) -> 45747 | P5: =IF(AND(Table1[[#This Row],[Date]]>=Table1[[#This Row],[Campaign Start Date]],Table1[[#This Row],[Date]]<=Table1[[#This Row],[Campaign End Date]]),"During Campaign","Before Campaign") -> Before Campaign
A6: P005 | B6: YouTube | C6: 2024-06-26 | D6: Reel | E6: Check out our latest reel on youtube! | F6: 3557 | G6: 687 | H6: 424 | I6: 71140 | J6: 70701 | K6: 224 | L6: #EVRevolution,#TeslaCoInnovation | M6: CybertruckLaunch | N6: =_xlfn.XLOOKUP(Table1[[#This Row],[Campaign_Name]],'Campaign Metadata'!A:A,'Campaign Metadata'!B:B,"Notfound",0) -> 45458 | O6: =_xlfn.XLOOKUP(Table1[[#This Row],[Campaign_Name]],'Campaign Metadata'!A:A,'Campaign Metadata'!C:C,"Not found",0) -> 45488 | P6: =IF(AND(Table1[[#This Row],[Date]]>=Table1[[#This Row],[Campaign Start Date]],Table1[[#This Row],[Date]]<=Table1[[#This Row],[Campaign End Date]]),"During Campaign","Before Campaign") -> Before Campaign
A7: P006 | B7: Facebook | C7: 2024-10-31 | D7: Carousel | E7: Check out our latest carousel on facebook! | F7: 2945 | G7: 930 | H7: 355 | I7: 23560 | J7: 23275 | K7: 256 | L7: #TeslaCoInnovation | M7: ModelYCampaign | N7: =_xlfn.XLOOKUP(Table1[[#This Row],[Campaign_Name]],'Campaign Metadata'!A:A,'Campaign Metadata'!B:B,"Notfound",0) -> 45566 | O7: =_xlfn.XLOOKUP(Table1[[#This Row],[Campaign_Name]],'Campaign Metadata'!A:A,'Campaign Metadata'!C:C,"Not found",0) -> 45596 | P7: =IF(AND(Table1[[#This Row],[Date]]>=Table1[[#This Row],[Campaign Start Date]],Table1[[#This Row],[Date]]<=Table1[[#This Row],[Campaign End Date]]),"During Campaign","Before Campaign") -> Before Campaign
A8: P007 | B8: Twitter | C8: 2024-06-24 | D8: Carousel | E8: Check out our latest carousel on twitter! | F8: 3860 | G8: 201 | H8: 279 | I8: 61760 | J8: 61660 | K8: 235 | L8: #TeslaCoInnovation | M8: ModelYCampaign | N8: =_xlfn.XLOOKUP(Table1[[#This Row],[Campaign_Name]],'Campaign Metadata'!A:A,'Campaign Metadata'!B:B,"Notfound",0) -> 45566 | O8: =_xlfn.XLOOKUP(Table1[[#This Row],[Campaign_Name]],'Campaign Metadata'!A:A,'Campaign Metadata'!C:C,"Not found",0) -> 45596 | P8: =IF(AND(Table1[[#This Row],[Date]]>=Table1[[#This Row],[Campaign Start Date]],Table1[[#This Row],[Date]]<=Table1[[#This Row],[Campaign End Date]]),"During Campaign","Before Campaign") -> Before Campaign
A9: P008 | B9: YouTube | C9: 2024-07-13 | D9: Image | E9: Check out our latest image on youtube! | F9: 3929 | G9: 262 | H9: 278 | I9: 43219 | J9: 42841 | K9: 39 | L9: #EVRevolution | M9: SustainabilityDrive | N9: =_xlfn.XLOOKUP(Table1[[#This Row],[Campaign_Name]],'Campaign Metadata'!A:A,'Campaign Metadata'!B:B,"Notfound",0) -> 45717 | O9: =_xlfn.XLOOKUP(Table1[[#This Row],[Campaign_Name]],'Campaign Metadata'!A:A,'Campaign Metadata'!C:C,"Not found",0) -> 45747 | P9: =IF(AND(Table1[[#This Row],[Date]]>=Table1[[#This Row],[Campaign Start Date]],Table1[[#This Row],[Date]]<=Table1[[#This Row],[Campaign End Date]]),"During Campaign","Before Campaign") -> Before Campaign
A10: P009 | B10: Facebook | C10: 2024-08-30 | D10: Text | E10: Check out our latest text on facebook! | F10: 3784 | G10: 808 | H10: 404 | I10: 56760 | J10: 56343 | K10: 131 | L10: #TeslaCoInnovation | M10: ModelYCampaign | N10: =_xlfn.XLOOKUP(Table1[[#This Row],[Campaign_Name]],'Campaign Metadata'!A:A,'Campaign Metadata'!B:B,"Notfound",0) -> 45566 | O10: =_xlfn.XLOOKUP(Table1[[#This Row],[Campaign_Name]],'Campaign Metadata'!A:A,'Campaign Metadata'!C:C,"Not found",0) -> 45596 | P10: =IF(AND(Table1[[#This Row],[Date]]>=Table1[[#This Row],[Campaign Start Date]],Table1[[#This Row],[Date]]<=Table1[[#This Row],[Campaign End Date]]),"During Campaign","Before Campaign") -> Before Campaign
A11: P010 | B11: Facebook | C11: 2025-03-11 | D11: Image | E11: Check out our latest image on facebook! | F11: 4241 | G11: 902 | H11: 47 | I11: 72097 | J11: 71598 | K11: 167 | L11: #TeslaCoInnovation | M11: ModelYCampaign | N11: =_xlfn.XLOOKUP(Table1[[#This Row],[Campaign_Name]],'Campaign Metadata'!A:A,'Campaign Metadata'!B:B,"Notfound",0) -> 45566 | O11: =_xlfn.XLOOKUP(Table1[[#This Row],[Campaign_Name]],'Campaign Metadata'!A:A,'Campaign Metadata'!C:C,"Not found",0) -> 45596 | P11: =IF(AND(Table1[[#This Row],[Date]]>=Table1[[#This Row],[Campaign Start Date]],Table1[[#This Row],[Date]]<=Table1[[#This Row],[Campaign End Date]]),"During Campaign","Before Campaign") -> Before Campaign
A12: P011 | B12: Instagram | C12: 2025-02-02 | D12: Story | E12: Check out our latest story on instagram! | F12: 1792 | G12: 614 | H12: 497 | I12: 25088 | J12: 24675 | K12: 65 | L12: #FutureOfDriving | M12: SustainabilityDrive | N12: =_xlfn.XLOOKUP(Table1[[#This Row],[Campaign_Name]],'Campaign Metadata'!A:A,'Campaign Metadata'!B:B,"Notfound",0) -> 45717 | O12: =_xlfn.XLOOKUP(Table1[[#This Row],[Campaign_Name]],'Campaign Metadata'!A:A,'Campaign Metadata'!C:C,"Not found",0) -> 45747 | P12: =IF(AND(Table1[[#This Row],[Date]]>=Table1[[#This Row],[Campaign Start Date]],Table1[[#This Row],[Date]]<=Table1[[#This Row],[Campaign End Date]]),"During Campaign","Before Campaign") -> Before Campaign
A13: P012 | B13: Facebook | C13: 2024-07-21 | D13: Reel | E13: Check out our latest reel on facebook! | F13: 1946 | G13: 686 | H13: 377 | I13: 23352 | J13: 22982 | K13: 213 | L13: #FutureOfDriving | M13: FSDUpdate | N13: =_xlfn.XLOOKUP(Table1[[#This Row],[Campaign_Name]],'Campaign Metadata'!A:A,'Campaign Metadata'!B:B,"Notfound",0) -> 45651 | O13: =_xlfn.XLOOKUP(Table1[[#This Row],[Campaign_Name]],'Campaign Metadata'!A:A,'Campaign Metadata'!C:C,"Not found",0) -> 45667 | P13: =IF(AND(Table1[[#This Row],[Date]]>=Table1[[#This Row],[Campaign Start Date]],Table1[[#This Row],[Date]]<=Table1[[#This Row],[Campaign End Date]]),"During Campaign","Before Campaign") -> Before Campaign
A14: P013 | B14: YouTube | C14: 2024-11-18 | D14: Carousel | E14: Check out our latest carousel on youtube! | F14: 1171 | G14: 286 | H14: 231 | I14: 22249 | J14: 21282 | K14: 114 | L14: #EVRevolution | M14: CybertruckLaunch | N14: =_xlfn.XLOOKUP(Table1[[#This Row],[Campaign_Name]],'Campaign Metadata'!A:A,'Campaign Metadata'!B:B,"Notfound",0) -> 45458 | O14: =_xlfn.XLOOKUP(Table1[[#This Row],[Campaign_Name]],'Campaign Metadata'!A:A,'Campaign Metadata'!C:C,"Not found",0) -> 45488 | P14: =IF(AND(Table1[[#This Row],[Date]]>=Table1[[#This Row],[Campaign Start Date]],Table1[[#This Row],[Date]]<=Table1[[#This Row],[Campaign End Date]]),"During Campaign","Before Campaign") -> Before Campaign
A15: P014 | B15: Facebook | C15: 2025-02-16 | D15: Story | E15: Check out our latest story on facebook! | F15: 4242 | G15: 555 | H15: 131 | I15: 33936 | J15: 33802 | K15: 265 | L15: #FutureOfDriving | N15: =_xlfn.XLOOKUP(Table1[[#This Row],[Campaign_Name]],'Campaign Metadata'!A:A,'Campaign Metadata'!B:B,"Notfound",0) -> 0 | O15: =_xlfn.XLOOKUP(Table1[[#This Row],[Campaign_Name]],'Campaign Metadata'!A:A,'Campaign Metadata'!C:C,"Not found",0) -> 0 | P15: =IF(AND(Table1[[#This Row],[Date]]>=Table1[[#This Row],[Campaign Start Date]],Table1[[#This Row],[Date]]<=Table1[[#This Row],[Campaign End Date]]),"During Campaign","Before Campaign") -> Before Campaign
A16: P015 | B16: Facebook | C16: 2024-10-24 | D16: Video | E16: Check out our latest video on facebook! | F16: 3888 | G16: 604 | H16: 128 | I16: 77760 | J16: 77167 | K16: 20 | L16: #FutureOfDriving | M16: CybertruckLaunch | N16: =_xlfn.XLOOKUP(Table1[[#This Row],[Campaign_Name]],'Campaign Metadata'!A:A,'Campaign Metadata'!B:B,"Notfound",0) -> 45458 | O16: =_xlfn.XLOOKUP(Table1[[#This Row],[Campaign_Name]],'Campaign Metadata'!A:A,'Campaign Metadata'!C:C,"Not found",0) -> 45488 | P16: =IF(AND(Table1[[#This Row],[Date]]>=Table1[[#This Row],[Campaign Start Date]],Table1[[#This Row],[Date]]<=Table1[[#This Row],[Campaign End Date]]),"During Campaign","Before Campaign") -> Before Campaign
A17: P016 | B17: Facebook | C17: 2024-08-26 | D17: Text | E17: Check out our latest text on facebook! | F17: 3452 | G17: 377 | H17: 360 | I17: 55232 | J17: 55075 | K17: 87 | L17: #FutureOfDriving | M17: FSDUpdate | N17: =_xlfn.XLOOKUP(Table1[[#This Row],[Campaign_Name]],'Campaign Metadata'!A:A,'Campaign Metadata'!B:B,"Notfound",0) -> 45651 | O17: =_xlfn.XLOOKUP(Table1[[#This Row],[Campaign_Name]],'Campaign Metadata'!A:A,'Campaign Metadata'!C:C,"Not found",0) -> 45667 | P17: =IF(AND(Table1[[#This Row],[Date]]>=Table1[[#This Row],[Campaign Start Date]],Table1[[#This Row],[Date]]<=Table1[[#This Row],[Campaign End Date]]),"During Campaign","Before Campaign") -> Before Campaign
A18: P017 | B18: Facebook | C18: 2025-05-05 | D18: Text | E18: Check out our latest text on facebook! | F18: 4441 | G18: 511 | H18: 70 | I18: 53292 | J18: 53082 | K18: 159 | L18: #EVRevolution | M18: SustainabilityDrive | N18: =_xlfn.XLOOKUP(Table1[[#This Row],[Campaign_Name]],'Campaign Metadata'!A:A,'Campaign Metadata'!B:B,"Notfound",0) -> 45717 | O18: =_xlfn.XLOOKUP(Table1[[#This Row],[Campaign_Name]],'Campaign Metadata'!A:A,'Campaign Metadata'!C:C,"Not found",0) -> 45747 | P18: =IF(AND(Table1[[#This Row],[Date]]>=Table1[[#This Row],[Campaign Start Date]],Table1[[#This Row],[Date]]<=Table1[[#This Row],[Campaign End Date]]),"During Campaign","Before Campaign") -> Before Campaign
A19: P018 | B19: Instagram | C19: 2024-08-19 | D19: Reel | E19: Check out our latest reel on instagram! | F19: 3000 | G19: 382 | H19: 325 | I19: 36000 | J19: 35819 | K19: 19 | L19: #FutureOfDriving | M19: CybertruckLaunch | N19: =_xlfn.XLOOKUP(Table1[[#This Row],[Campaign_Name]],'Campaign Metadata'!A:A,'Campaign Metadata'!B:B,"Notfound",0) -> 45458 | O19: =_xlfn.XLOOKUP(Table1[[#This Row],[Campaign_Name]],'Campaign Metadata'!A:A,'Campaign Metadata'!C:C,"Not found",0) -> 45488 | P19: =IF(AND(Table1[[#This Row],[Date]]>=Table1[[#This Row],[Campaign Start Date]],Table1[[#This Row],[Date]]<=Table1[[#This Row],[Campaign End Date]]),"During Campaign","Before Campaign") -> Before Campaign
A20: P019 | B20: Instagram | C20: 2024-06-23 | D20: Video | E20: Check out our latest video on instagram! | F20: 1071 | G20: 519 | H20: 22 | I20: 16065 | J20: 15865 | K20: 103 | L20: #TeslaCoInnovation | M20: SustainabilityDrive | N20: =_xlfn.XLOOKUP(Table1[[#This Row],[Campaign_Name]],'Campaign Metadata'!A:A,'Campaign Metadata'!B:B,"Notfound",0) -> 45717 | O20: =_xlfn.XLOOKUP(Table1[[#This Row],[Campaign_Name]],'Campaign Metadata'!A:A,'Campaign Metadata'!C:C,"Not found",0) -> 45747 | P20: =IF(AND(Table1[[#This Row],[Date]]>=Table1[[#This Row],[Campaign Start Date]],Table1[[#This Row],[Date]]<=Table1[[#This Row],[Campaign End Date]]),"During Campaign","Before Campaign") -> Before Campaign
A21: P020 | B21: Instagram | C21: 2024-09-09 | D21: Carousel | E21: Check out our latest carousel on instagram! | F21: 4054 | G21: 488 | H21: 373 | I21: 77026 | J21: 76881 | K21: 25 | L21: #TeslaCoInnovation | M21: CybertruckLaunch | N21: =_xlfn.XLOOKUP(Table1[[#This Row],[Campaign_Name]],'Campaign Metadata'!A:A,'Campaign Metadata'!B:B,"Notfound",0) -> 45458 | O21: =_xlfn.XLOOKUP(Table1[[#This Row],[Campaign_Name]],'Campaign Metadata'!A:A,'Campaign Metadata'!C:C,"Not found",0) -> 45488 | P21: =IF(AND(Table1[[#This Row],[Date]]>=Table1[[#This Row],[Campaign Start Date]],Table1[[#This Row],[Date]]<=Table1[[#This Row],[Campaign End Date]]),"During Campaign","Before Campaign") -> Before Campaign
A22: P021 | B22: Instagram | C22: 2025-01-04 | D22: Reel | E22: Check out our latest reel on instagram! | F22: 4838 | G22: 640 | H22: 128 | I22: 72570 | J22: 72396 | K22: 83 | L22: #FutureOfDriving | M22: SustainabilityDrive | N22: =_xlfn.XLOOKUP(Table1[[#This Row],[Campaign_Name]],'Campaign Metadata'!A:A,'Campaign Metadata'!B:B,"Notfound",0) -> 45717 | O22: =_xlfn.XLOOKUP(Table1[[#This Row],[Campaign_Name]],'Campaign Metadata'!A:A,'Campaign Metadata'!C:C,"Not found",0) -> 45747 | P22: =IF(AND(Table1[[#This Row],[Date]]>=Table1[[#This Row],[Campaign Start Date]],Table1[[#This Row],[Date]]<=Table1[[#This Row],[Campaign End Date]]),"During Campaign","Before Campaign") -> Before Campaign
A23: P022 | B23: Facebook | C23: 2025-02-27 | D23: Text | E23: Check out our latest text on facebook! | F23: 1570 | G23: 187 | H23: 260 | I23: 25120 | J23: 24613 | K23: 133 | L23: #TeslaCoInnovation | M23: SustainabilityDrive | N23: =_xlfn.XLOOKUP(Table1[[#This Row],[Campaign_Name]],'Campaign Metadata'!A:A,'Campaign Metadata'!B:B,"Notfound",0) -> 45717 | O23: =_xlfn.XLOOKUP(Table1[[#This Row],[Campaign_Name]],'Campaign Metadata'!A:A,'Campaign Metadata'!C:C,"Not found",0) -> 45747 | P23: =IF(AND(Table1[[#This Row],[Date]]>=Table1[[#This Row],[Campaign Start Date]],Table1[[#This Row],[Date]]<=Table1[[#This Row],[Campaign End Date]]),"During Campaign","Before Campaign") -> Before Campaign
A24: P023 | B24: Facebook | C24: 2024-11-06 | D24: Video | E24: Check out our latest video on facebook! | F24: 1606 | G24: 547 | H24: 316 | I24: 32120 | J24: 31736 | K24: 225 | L24: #TeslaCoInnovation,#AnytimeIsTeslaTime | M24: ModelYCampaign | N24: =_xlfn.XLOOKUP(Table1[[#This Row],[Campaign_Name]],'Campaign Metadata'!A:A,'Campaign Metadata'!B:B,"Notfound",0) -> 45566 | O24: =_xlfn.XLOOKUP(Table1[[#This Row],[Campaign_Name]],'Campaign Metadata'!A:A,'Campaign Metadata'!C:C,"Not found",0) -> 45596 | P24: =IF(AND(Table1[[#This Row],[Date]]>=Table1[[#This Row],[Campaign Start Date]],Table1[[#This Row],[Date]]<=Table1[[#This Row],[Campaign End Date]]),"During Campaign","Before Campaign") -> Before Campaign
A25: P024 | B25: Facebook | C25: 2025-01-23 | D25: Video | E25: Check out our latest video on facebook! | F25: 3961 | G25: 761 | H25: 131 | I25: 67337 | J25: 66615 | K25: 161 | L25: #FutureOfDriving | M25: FSDUpdate | N25: =_xlfn.XLOOKUP(Table1[[#This Row],[Campaign_Name]],'Campaign Metadata'!A:A,'Campaign Metadata'!B:B,"Notfound",0) -> 45651 | O25: =_xlfn.XLOOKUP(Table1[[#This Row],[Campaign_Name]],'Campaign Metadata'!A:A,'Campaign Metadata'!C:C,"Not found",0) -> 45667 | P25: =IF(AND(Table1[[#This Row],[Date]]>=Table1[[#This Row],[Campaign Start Date]],Table1[[#This Row],[Date]]<=Table1[[#This Row],[Campaign End Date]]),"During Campaign","Before Campaign") -> Before Campaign
A26: P025 | B26: Twitter | C26: 2025-04-10 | D26: Carousel | E26: Check out our latest carousel on twitter! | F26: 3128 | G26: 211 | H26: 197 | I26: 59432 | J26: 59182 | K26: 238 | L26: #EVRevolution | N26: =_xlfn.XLOOKUP(Table1[[#This Row],[Campaign_Name]],'Campaign Metadata'!A:A,'Campaign Metadata'!B:B,"Notfound",0) -> 0 | O26: =_xlfn.XLOOKUP(Table1[[#This Row],[Campaign_Name]],'Campaign Metadata'!A:A,'Campaign Metadata'!C:C,"Not found",0) -> 0 | P26: =IF(AND(Table1[[#This Row],[Date]]>=Table1[[#This Row],[Campaign Start Date]],Table1[[#This Row],[Date]]<=Table1[[#This Row],[Campaign End Date]]),"During Campaign","Before Campaign") -> Before Campaign
A27: P026 | B27: YouTube | C27: 2025-04-05 | D27: Reel | E27: Check out our latest reel on youtube! | F27: 3009 | G27: 413 | H27: 358 | I27: 42126 | J27: 41309 | K27: 211 | L27: #FutureOfDriving | M27: ModelYCampaign | N27: =_xlfn.XLOOKUP(Table1[[#This Row],[Campaign_Name]],'Campaign Metadata'!A:A,'Campaign Metadata'!B:B,"Notfound",0) -> 45566 | O27: =_xlfn.XLOOKUP(Table1[[#This Row],[Campaign_Name]],'Campaign Metadata'!A:A,'Campaign Metadata'!C:C,"Not found",0) -> 45596 | P27: =IF(AND(Table1[[#This Row],[Date]]>=Table1[[#This Row],[Campaign Start Date]],Table1[[#This Row],[Date]]<=Table1[[#This Row],[Campaign End Date]]),"During Campaign","Before Campaign") -> Before Campaign
A28: P027 | B28: YouTube | C28: 2024-09-17 | D28: Text | E28: Check out our latest text on youtube! | F28: 2076 | G28: 195 | H28: 104 | I28: 33216 | J28: 32244 | K28: 51 | L28: #FutureOfDriving | M28: SustainabilityDrive | N28: =_xlfn.XLOOKUP(Table1[[#This Row],[Campaign_Name]],'Campaign Metadata'!A:A,'Campaign Metadata'!B:B,"Notfound",0) -> 45717 | O28: =_xlfn.XLOOKUP(Table1[[#This Row],[Campaign_Name]],'Campaign Metadata'!A:A,'Campaign Metadata'!C:C,"Not found",0) -> 45747 | P28: =IF(AND(Table1[[#This Row],[Date]]>=Table1[[#This Row],[Campaign Start Date]],Table1[[#This Row],[Date]]<=Table1[[#This Row],[Campaign End Date]]),"During Campaign","Before Campaign") -> Before Campaign
A29: P028 | B29: Instagram | C29: 2025-03-04 | D29: Video | E29: Check out our latest video on instagram! | F29: 432 | G29: 624 | H29: 123 | I29: 6912 | J29: 6259 | K29: 79 | L29: #FutureOfDriving | M29: SustainabilityDrive | N29: =_xlfn.XLOOKUP(Table1[[#This Row],[Campaign_Name]],'Campaign Metadata'!A:A,'Campaign Metadata'!B:B,"Notfound",0) -> 45717 | O29: =_xlfn.XLOOKUP(Table1[[#This Row],[Campaign_Name]],'Campaign Metadata'!A:A,'Campaign Metadata'!C:C,"Not found",0) -> 45747 | P29: =IF(AND(Table1[[#This Row],[Date]]>=Table1[[#This Row],[Campaign Start Date]],Table1[[#This Row],[Date]]<=Table1[[#This Row],[Campaign End Date]]),"During Campaign","Before Campaign") -> Before Campaign
A30: P029 | B30: Instagram | C30: 2025-01-31 | D30: Carousel | E30: Check out our latest carousel on instagram! | F30: 2566 | G30: 118 | H30: 37 | I30: 12830 | J30: 12264 | K30: 221 | L30: #FutureOfDriving | M30: FSDUpdate | N30: =_xlfn.XLOOKUP(Table1[[#This Row],[Campaign_Name]],'Campaign Metadata'!A:A,'Campaign Metadata'!B:B,"Notfound",0) -> 45651 | O30: =_xlfn.XLOOKUP(Table1[[#This Row],[Campaign_Name]],'Campaign Metadata'!A:A,'Campaign Metadata'!C:C,"Not found",0) -> 45667 | P30: =IF(AND(Table1[[#This Row],[Date]]>=Table1[[#This Row],[Campaign Start Date]],Table1[[#This Row],[Date]]<=Table1[[#This Row],[Campaign End Date]]),"During Campaign","Before Campaign") -> Before Campaign
A31: P030 | B31: Instagram | C31: 2025-02-25 | D31: Video | E31: Check out our latest video on instagram! | F31: 3095 | G31: 39 | H31: 78 | I31: 55710 | J31: 54808 | K31: 93 | L31: #EVRevolution | N31: =_xlfn.XLOOKUP(Table1[[#This Row],[Campaign_Name]],'Campaign Metadata'!A:A,'Campaign Metadata'!B:B,"Notfound",0) -> 0 | O31: =_xlfn.XLOOKUP(Table1[[#This Row],[Campaign_Name]],'Campaign Metadata'!A:A,'Campaign Metadata'!C:C,"Not found",0) -> 0 | P31: =IF(AND(Table1[[#This Row],[Date]]>=Table1[[#This Row],[Campaign Start Date]],Table1[[#This Row],[Date]]<=Table1[[#This Row],[Campaign End Date]]),"During Campaign","Before Campaign") -> Before Campaign
A32: P031 | B32: Instagram | C32: 2024-12-16 | D32: Text | E32: Check out our latest text on instagram! | F32: 438 | G32: 153 | H32: 275 | I32: 3066 | J32: 2701 | K32: 282 | L32: #TeslaCoInnovation | M32: ModelYCampaign | N32: =_xlfn.XLOOKUP(Table1[[#This Row],[Campaign_Name]],'Campaign Metadata'!A:A,'Campaign Metadata'!B:B,"Notfound",0) -> 45566 | O32: =_xlfn.XLOOKUP(Table1[[#This Row],[Campaign_Name]],'Campaign Metadata'!A:A,'Campaign Metadata'!C:C,"Not found",0) -> 45596 | P32: =IF(AND(Table1[[#This Row],[Date]]>=Table1[[#This Row],[Campaign Start Date]],Table1[[#This Row],[Date]]<=Table1[[#This Row],[Campaign End Date]]),"During Campaign","Before Campaign") -> Before Campaign
A33: P032 | B33: Twitter | C33: 2024-07-31 | D33: Carousel | E33: Check out our latest carousel on twitter! | F33: 2278 | G33: 10 | H33: 321 | I33: 13668 | J33: 12676 | K33: 275 | L33: #EVRevolution | M33: CybertruckLaunch | N33: =_xlfn.XLOOKUP(Table1[[#This Row],[Campaign_Name]],'Campaign Metadata'!A:A,'Campaign Metadata'!B:B,"Notfound",0) -> 45458 | O33: =_xlfn.XLOOKUP(Table1[[#This Row],[Campaign_Name]],'Campaign Metadata'!A:A,'Campaign Metadata'!C:C,"Not found",0) -> 45488 | P33: =IF(AND(Table1[[#This Row],[Date]]>=Table1[[#This Row],[Campaign Start Date]],Table1[[#This Row],[Date]]<=Table1[[#This Row],[Campaign End Date]]),"During Campaign","Before Campaign") -> Before Campaign
A34: P033 | B34: Facebook | C34: 2024-08-21 | D34: Image | E34: Check out our latest image on facebook! | F34: 1407 | G34: 400 | H34: 351 | I34: 16884 | J34: 15954 | K34: 113 | L34: #TeslaCoInnovation | M34: CybertruckLaunch | N34: =_xlfn.XLOOKUP(Table1[[#This Row],[Campaign_Name]],'Campaign Metadata'!A:A,'Campaign Metadata'!B:B,"Notfound",0) -> 45458 | O34: =_xlfn.XLOOKUP(Table1[[#This Row],[Campaign_Name]],'Campaign Metadata'!A:A,'Campaign Metadata'!C:C,"Not found",0) -> 45488 | P34: =IF(AND(Table1[[#This Row],[Date]]>=Table1[[#This Row],[Campaign Start Date]],Table1[[#This Row],[Date]]<=Table1[[#This Row],[Campaign End Date]]),"During Campaign","Before Campaign") -> Before Campaign
A35: P034 | B35: Facebook | C35: 2025-03-26 | D35: Text | E35: Check out our latest text on facebook! | F35: 1652 | G35: 89 | H35: 357 | I35: 29736 | J35: 28771 | K35: 215 | L35: #TeslaCoInnovation | M35: FSDUpdate | N35: =_xlfn.XLOOKUP(Table1[[#This Row],[Campaign_Name]],'Campaign Metadata'!A:A,'Campaign Metadata'!B:B,"Notfound",0) -> 45651 | O35: =_xlfn.XLOOKUP(Table1[[#This Row],[Campaign_Name]],'Campaign Metadata'!A:A,'Campaign Metadata'!C:C,"Not found",0) -> 45667 | P35: =IF(AND(Table1[[#This Row],[Date]]>=Table1[[#This Row],[Campaign Start Date]],Table1[[#This Row],[Date]]<=Table1[[#This Row],[Campaign End Date]]),"During Campaign","Before Campaign") -> Before Campaign
A36: P035 | B36: Instagram | C36: 2024-11-30 | D36: Video | E36: Check out our latest video on instagram! | F36: 3775 | G36: 16 | H36: 239 | I36: 33975 | J36: 33310 | K36: 271 | L36: #FutureOfDriving | M36: ModelYCampaign | N36: =_xlfn.XLOOKUP(Table1[[#This Row],[Campaign_Name]],'Campaign Metadata'!A:A,'Campaign Metadata'!B:B,"Notfound",0) -> 45566 | O36: =_xlfn.XLOOKUP(Table1[[#This Row],[Campaign_Name]],'Campaign Metadata'!A:A,'Campaign Metadata'!C:C,"Not found",0) -> 45596 | P36: =IF(AND(Table1[[#This Row],[Date]]>=Table1[[#This Row],[Campaign Start Date]],Table1[[#This Row],[Date]]<=Table1[[#This Row],[Campaign End Date]]),"During Campaign","Before Campaign") -> Before Campaign
A37: P036 | B37: Instagram | C37: 2025-04-19 | D37: Story | E37: Check out our latest story on instagram! | F37: 4518 | G37: 285 | H37: 383 | I37: 67770 | J37: 67621 | K37: 31 | L37: #EVRevolution | M37: ModelYCampaign | N37: =_xlfn.XLOOKUP(Table1[[#This Row],[Campaign_Name]],'Campaign Metadata'!A:A,'Campaign Metadata'!B:B,"Notfound",0) -> 45566 | O37: =_xlfn.XLOOKUP(Table1[[#This Row],[Campaign_Name]],'Campaign Metadata'!A:A,'Campaign Metadata'!C:C,"Not found",0) -> 45596 | P37: =IF(AND(Table1[[#This Row],[Date]]>=Table1[[#This Row],[Campaign Start Date]],Table1[[#This Row],[Date]]<=Table1[[#This Row],[Campaign End Date]]),"During Campaign","Before Campaign") -> Before Campaign
A38: P037 | B38: Facebook | C38: 2025-01-06 | D38: Carousel | E38: Check out our latest carousel on facebook! | F38: 3024 | G38: 925 | H38: 350 | I38: 24192 | J38: 23518 | K38: 36 | L38: #EVRevolution | M38: ModelYCampaign | N38: =_xlfn.XLOOKUP(Table1[[#This Row],[Campaign_Name]],'Campaign Metadata'!A:A,'Campaign Metadata'!B:B,"Notfound",0) -> 45566 | O38: =_xlfn.XLOOKUP(Table1[[#This Row],[Campaign_Name]],'Campaign Metadata'!A:A,'Campaign Metadata'!C:C,"Not found",0) -> 45596 | P38: =IF(AND(Table1[[#This Row],[Date]]>=Table1[[#This Row],[Campaign Start Date]],Table1[[#This Row],[Date]]<=Table1[[#This Row],[Campaign End Date]]),"During Campaign","Before Campaign") -> Before Campaign
A39: P038 | B39: YouTube | C39: 2025-02-17 | D39: Reel | E39: Check out our latest reel on youtube! | F39: 3138 | G39: 123 | H39: 291 | I39: 28242 | J39: 27550 | K39: 87 | L39: #TeslaCoInnovation | M39: SustainabilityDrive | N39: =_xlfn.XLOOKUP(Table1[[#This Row],[Campaign_Name]],'Campaign Metadata'!A:A,'Campaign Metadata'!B:B,"Notfound",0) -> 45717 | O39: =_xlfn.XLOOKUP(Table1[[#This Row],[Campaign_Name]],'Campaign Metadata'!A:A,'Campaign Metadata'!C:C,"Not found",0) -> 45747 | P39: =IF(AND(Table1[[#This Row],[Date]]>=Table1[[#This Row],[Campaign Start Date]],Table1[[#This Row],[Date]]<=Table1[[#This Row],[Campaign End Date]]),"During Campaign","Before Campaign") -> Before Campaign
A40: P039 | B40: Facebook | C40: 2024-11-25 | D40: Image | E40: Check out our latest image on facebook! | F40: 3564 | G40: 629 | H40: 177 | I40: 60588 | J40: 59627 | K40: 92 | L40: #TeslaCoInnovation | N40: =_xlfn.XLOOKUP(Table1[[#This Row],[Campaign_Name]],'Campaign Metadata'!A:A,'Campaign Metadata'!B:B,"Notfound",0) -> 0 | O40: =_xlfn.XLOOKUP(Table1[[#This Row],[Campaign_Name]],'Campaign Metadata'!A:A,'Campaign Metadata'!C:C,"Not found",0) -> 0 | P40: =IF(AND(Table1[[#This Row],[Date]]>=Table1[[#This Row],[Campaign Start Date]],Table1[[#This Row],[Date]]<=Table1[[#This Row],[Campaign End Date]]),"During Campaign","Before Campaign") -> Before Campaign
...

Sheet Engagement Summary
A1: Week_Start_Date | B1: Platform | C1: New_Followers | D1: Unfollows | E1: Total_Followers | F1: Engagement_Rate | G1: Ad_Spend | H1: Net Follower | I1: Follower Growth Rate | J1: week number
A2: 2024-06-03 | B2: Instagram | C2: 1135 | D2: 88 | E2: 344084 | F2: 8.06 | G2: 5904 | H2: =C2-D2 -> 1047 | I2: =(C2-D2)/E2 -> 0.0030428616 | J2: =WEEKNUM(Table4[[#This Row],[Week_Start_Date]]) -> 23
A3: 2024-06-03 | B3: Facebook | C3: 1312 | D3: 310 | E3: 42654 | F3: 4.98 | G3: 9566 | H3: =C3-D3 -> 1002 | I3: =(C3-D3)/E3 -> 0.023491349 | J3: =WEEKNUM(Table4[[#This Row],[Week_Start_Date]]) -> 23
A4: 2024-06-03 | B4: Twitter | C4: 584 | D4: 169 | E4: 146834 | F4: 8.31 | G4: 26752 | H4: =C4-D4 -> 415 | I4: =(C4-D4)/E4 -> 0.0028263209 | J4: =WEEKNUM(Table4[[#This Row],[Week_Start_Date]]) -> 23
A5: 2024-06-03 | B5: YouTube | C5: 1535 | D5: 445 | E5: 395536 | F5: 4.11 | G5: 30671 | H5: =C5-D5 -> 1090 | I5: =(C5-D5)/E5 -> 0.0027557542 | J5: =WEEKNUM(Table4[[#This Row],[Week_Start_Date]]) -> 23
A6: 2024-06-10 | B6: Instagram | C6: 656 | D6: 139 | E6: 49157 | F6: 9.05 | G6: 9920 | H6: =C6-D6 -> 517 | I6: =(C6-D6)/E6 -> 0.010517322 | J6: =WEEKNUM(Table4[[#This Row],[Week_Start_Date]]) -> 24
A7: 2024-06-10 | B7: Facebook | C7: 1697 | D7: 414 | E7: 316555 | F7: 2.37 | G7: 7924 | H7: =C7-D7 -> 1283 | I7: =(C7-D7)/E7 -> 0.0040530082 | J7: =WEEKNUM(Table4[[#This Row],[Week_Start_Date]]) -> 24
A8: 2024-06-10 | B8: Twitter | C8: 436 | D8: 250 | E8: 254347 | F8: 4.01 | G8: 8912 | H8: =C8-D8 -> 186 | I8: =(C8-D8)/E8 -> 0.00073128443 | J8: =WEEKNUM(Table4[[#This Row],[Week_Start_Date]]) -> 24
A9: 2024-06-10 | B9: YouTube | C9: 1197 | D9: 203 | E9: 413878 | F9: 3.16 | G9: 21205 | H9: =C9-D9 -> 994 | I9: =(C9-D9)/E9 -> 0.0024016739 | J9: =WEEKNUM(Table4[[#This Row],[Week_Start_Date]]) -> 24
A10: 2024-06-17 | B10: Instagram | C10: 1048 | D10: 155 | E10: 456946 | F10: 2.46 | G10: 11329 | H10: =C10-D10 -> 893 | I10: =(C10-D10)/E10 -> 0.0019542791 | J10: =WEEKNUM(Table4[[#This Row],[Week_Start_Date]]) -> 25
A11: 2024-06-17 | B11: Facebook | C11: 1753 | D11: 371 | E11: 169496 | F11: 8.11 | G11: 46670 | H11: =C11-D11 -> 1382 | I11: =(C11-D11)/E11 -> 0.0081535847 | J11: =WEEKNUM(Table4[[#This Row],[Week_Start_Date]]) -> 25
A12: 2024-06-17 | B12: Twitter | C12: 1335 | D12: 40 | E12: 122732 | F12: 8.19 | G12: 22482 | H12: =C12-D12 -> 1295 | I12: =(C12-D12)/E12 -> 0.010551445 | J12: =WEEKNUM(Table4[[#This Row],[Week_Start_Date]]) -> 25
A13: 2024-06-17 | B13: YouTube | C13: 403 | D13: 66 | E13: 382851 | F13: 3.49 | G13: 24313 | H13: =C13-D13 -> 337 | I13: =(C13-D13)/E13 -> 0.000880238 | J13: =WEEKNUM(Table4[[#This Row],[Week_Start_Date]]) -> 25
